<?xml version="1.0"?>
<robot name="demo">

  <material name="black">
    <color rgba="0 0 0 0.5"/>
  </material>
  <material name="white">
    <color rgba="1 1 1 0.5"/>
  </material>
  <material name="red">
    <color rgba="1 0 0 0.5"/>
  </material>
  <material name="green">
    <color rgba="0 1 0 0.5"/>
  </material>
  <material name="blue">
    <color rgba="0 0 1 0.5"/>
  </material>

  <link name="base_link">
    <visual>
      <geometry>
        <cylinder length="1.0" radius="0.4"/>
      </geometry>
      <origin xyz="0 0 0.5" rpy="0 0 0"/>
      <material name="red"/>
    </visual>
  </link>

  <link name="first_link">
    <visual>
      <geometry>
        <cylinder length="1.0" radius="0.2"/>
      </geometry>
      <origin xyz="0 0 0.5" rpy="0 0 0"/>
      <material name="green"/>
    </visual>
  </link>

  <link name="second_link">
    <visual>
      <geometry>
        <cylinder length="1.0" radius="0.1"/>
      </geometry>
      <origin xyz="0 0 0.5" rpy="0 0 0"/>
      <material name="blue"/>
    </visual>
  </link>

  <joint name="first_joint" type="prismatic">
    <parent link="base_link"/>
    <child link="first_link"/>
    <axis xyz="0 0 1"/>
    <limit effort="1000.0" lower="0" upper="1" velocity="0.5"/>
    <origin xyz="0 0 0" rpy="0 0 0"/>
  </joint>

  <joint name="second_joint" type="prismatic">
    <parent link="first_link"/>
    <child link="second_link"/>
    <axis xyz="0 0 1"/>
    <limit effort="1000.0" lower="0" upper="1" velocity="0.5"/>
    <origin xyz="0 0 0" rpy="0 0 0"/>
  </joint>

</robot>
